Workbook
Name OVOTEL: #N/A

Sheet Marge Brut
B2: Marge Brut | C2: TURNOVER | E2: STOCK | I2: TOTAL | M2: Consumption | N2: Ratio %
B3: Summary | C3: Incl. | D3: Excl. VAT | E3: Opening | F3: Purchases | G3: Reverse | H3: New | I3: All | J3: Closing | K3: Staff | L3: Complimentary. | M3: Month | N3: M.B.
C4: VAT | D4: Month | E4: Stock | G4: Provisions | H4: Provisions | I4: Stocks | J4: Stock | K4: Meal | N4: Month
B5: TOTAL FOOD | C5: =14394.35+2718.7 -> 17113.05 | D5: =+C5/1.2 -> 14260.875 | E5: =SUM(E6:E7) -> 2381.14 | F5: ='Food Purchases'!D1 -> 4562.64 | G5: =SUM(G6:G7) -> 1092.6 | H5: =+H6+H7 -> 912.17 | I5: =SUM(I6:I7) -> 6763.35 | J5: =+J6+J7 -> 1879.36 | K5: =+Comps!E18 -> 306.4 | L5: =+Comps!G44+Comps!G48+Comps!G74+Comps!G100 -> 8.7175 | M5: =+I5-J5-K5-L5 -> 4568.8725 | N5: =+M5/D5 -> 0.32037813
B6: Total Food - (Breakfast) | C6: =+C5-C7 -> 17113.05 | D6: =+C6/1.2 -> 14260.875 | E6: 2381.14 | F6: =+'Food HOTEL'!F3+G6 -> 1092.6 | G6: 1092.6 | H6: ='Food HOTEL'!N3 -> 0 | I6: =+E6+F6-G6+H6 -> 2381.14 | J6: 1879.36 | L6: =+L5-L7 -> 8.7175 | M6: =+I6-J6-K6-L6 -> 493.0625 | N6: =+M6/D6 -> 0.034574491
B7: Total Breakfast | D7: =+C7/1.2 -> 0 | F7: ='Food HOTEL'!E3+G7 -> 3470.04 | H7: ='Food HOTEL'!M3 -> 912.17 | I7: =+E7+F7-G7+H7 -> 4382.21 | L7: =+Comps!G30+Comps!G60+Comps!G86 -> 0 | M7: =+I7-J7-K7-L7 -> 4382.21 | N7: =+M7/D7 -> #DIV/0!
B8: WINES | C8: 505.65 | D8: =+C8/1.2 -> 421.375 | E8: 446.46 | F8: ='Beverage HOTEL'!E3+G8 -> 0 | H8: ='Beverage HOTEL'!O3 -> 0 | I8: =+E8+F8-G8+H8 -> 446.46 | J8: 261.51 | L8: =+Comps!B44+Comps!B48+Comps!B74+Comps!B100 -> 61.66875 | M8: =+I8-J8-K8-L8 -> 123.28125 | N8: =+M8/D8 -> 0.29256897
B9: BOTTLED BEER | C9: 564.3 | D9: =+C9/1.2 -> 470.25 | E9: 295.93 | F9: ='Beverage HOTEL'!F3+G9 -> 0 | H9: ='Beverage HOTEL'!P3 -> 0 | I9: =+E9+F9-G9+H9 -> 295.93 | J9: 126.15 | L9: =+Comps!C44+Comps!C48+Comps!C74+Comps!C100 -> 69.6025 | M9: =+I9-J9-K9-L9 -> 100.1775 | N9: =+M9/D9 -> 0.2130303
B10: SOFT DRINKS ONLY | C10: 261.5 | D10: =+C10/1.2 -> 217.91667 | E10: 520.24 | F10: ='Beverage HOTEL'!G3+G10 -> 0 | H10: ='Beverage HOTEL'!Q3 -> 0 | I10: =+E10+F10-G10+H10 -> 520.24 | J10: 406.09 | L10: =+Comps!D44+Comps!D48+Comps!D74+Comps!D100 -> 40.2325 | M10: =+I10-J10-K10-L10 -> 73.9175 | N10: =+M10/D10 -> 0.33920076
B11: SPIRIT | C11: 193.65 | D11: =+C11/1.2 -> 161.375 | E11: 685.39 | F11: ='Beverage HOTEL'!H3+G11 -> 0 | H11: ='Beverage HOTEL'!R3 -> 0 | I11: =+E11+F11-G11+H11 -> 685.39 | J11: 640.72 | L11: =+Comps!E44+Comps!E48+Comps!E74+Comps!E100 -> 0 | M11: =+I11-J11-K11-L11 -> 44.67 | N11: =+M11/D11 -> 0.27680868
B12: TOTAL BEVERAGE | C12: =SUM(C8:C11) -> 1525.1 | D12: =SUM(D8:D11) -> 1270.9167 | E12: =SUM(E8:E11) -> 1948.02 | F12: ='Beverage Purchases'!D1 -> 0 | G12: =SUM(G8:G11) -> 0 | H12: =SUM(H8:H11) -> 0 | I12: =SUM(I8:I11) -> 1948.02 | J12: =SUM(J8:J11) -> 1434.47 | L12: =SUM(L8:L11) -> 171.50375 | M12: =SUM(M8:M11) -> 342.04625 | N12: =+M12/D12 -> 0.2691335
B13: GRAND TOTAL VR | C13: =+C5+C12 -> 18638.15 | D13: =+D5+D12 -> 15531.792 | E13: =+E5+E12 -> 4329.16 | F13: =+F5+F12 -> 4562.64 | G13: =+G5+G12 -> 1092.6 | H13: =+H5+H12 -> 912.17 | I13: =+I5+I12 -> 8711.37 | J13: =+J5+J12 -> 3313.83 | ... M13: =+M5+M12 -> 4910.9187 | N13: =+M13/D13 -> 0.31618495
B14: GRAND TOTAL FOLS | C14: 18638.15 | F14: =+C13-C14 -> 0 | G14: Must be 0
B15: Purchases Control | C15: Beverage | F15: =+F12-F11-F10-F9-F8 -> 0 | G15: Must be 0 | J15: by accountant
B16: Purchases Control | C16: Food | F16: =F5-F6-F7 -> 0 | G16: Must be 0 | J16: by hotel
C17: F&B Manager | F17: General Manager | J17: Accountant

Sheet Food Purchases
C1: Total | D1: =SUM(D3:D477) -> 4562.64
A2: INVOICE NUMBER | B2: SUPPLIER | C2: DATE | D2: AMOUNT
A3: REVERSE PROVISONS (-) M-1
A4: 40268855 | B4: Bidfood / BFS Group Ltd T/A 3663 (Food) | C4: 45931 | D4: 218.7
A5: 40230696 | B5: Bidfood / BFS Group Ltd T/A 3663 (Food) | C5: 45931 | D5: 291.79
A6: 40326614 | B6: Bidfood / BFS Group Ltd T/A 3663 (Food) | C6: 45932 | D6: 185.38
A7: 40369535 | B7: Bidfood / BFS Group Ltd T/A 3663 (Food) | C7: 45934 | D7: 145.44
A8: 40369535 | B8: Bidfood / BFS Group Ltd T/A 3663 (Food) | C8: 45934 | D8: 77.52
A9: 94133662 | B9: Bidfood / BFS Group Ltd T/A 3663 (Food) | C9: 45937 | D9: -64.85
A10: 40414366 | B10: Bidfood / BFS Group Ltd T/A 3663 (Food) | C10: 45937 | D10: 177.37
A11: 40462673 | B11: Bidfood / BFS Group Ltd T/A 3663 (Food) | C11: 45939 | D11: 181.01
A12: 40509493 | B12: Bidfood / BFS Group Ltd T/A 3663 (Food) | C12: 45941 | D12: 378.7
A13: 40509493 | B13: Bidfood / BFS Group Ltd T/A 3663 (Food) | C13: 45941 | D13: 9.68
A14: 94144660 | B14: Bidfood / BFS Group Ltd T/A 3663 (Food) | C14: 45944 | D14: -9.2
A15: 40549088 | B15: Bidfood / BFS Group Ltd T/A 3663 (Food) | C15: 45944 | D15: 329.98
... A49: Petty Cash | B49: Soldo | C49: 45942 | D49: 5.25

Sheet Beverage Purchases
C1: Total | D1: =SUM(D3:D492) -> 0
A2: INVOICE NUMBER | B2: SUPPLIER | C2: DATE | D2: AMOUNT
A3: REVERSE PROVISONS (-) M-1
B4: MATTHEW CLARK BIBENDUM LTD
B5: MATTHEW CLARK BIBENDUM LTD
B6: MATTHEW CLARK BIBENDUM LTD

Sheet Food HOTEL
A1: Food Invoices from Hotel | I1: Food Provisions (Invoices sent After cut off)
A2: Supplier | B2: SENT | C2: Date | D2: Invoice number | E2: Breakfast Food Excl. VAT | F2: Other Food Excl. VAT | G2: Food Excl. VAT | I2: Supplier | J2: SENT | K2: Date | L2: Invoice number | M2: Breakfast Food Excl. VAT | N2: Other Food Excl. VAT | O2: Food Excl. VAT
A3: Monthly amount | E3: =SUM(E4:E292) -> 3470.04 | F3: =SUM(F4:F292) -> 0 | G3: =SUM(G4:G292) -> 3470.04 | I3: Monthly amount | M3: =SUM(M5:M292) -> 912.17 | N3: =SUM(N4:N292) -> 0 | O3: =SUM(O4:O292) -> 912.17 | Q3: SUPPLIERS
A4: REVERSE PROVISONS (-) M-1 | E4: -1092.6 | G4: =E4+F4 -> -1092.6 | O4: =M4+N4 -> 0 | Q4: REVERSE PROVISONS (-) M-1 | R4: YES
G5: =E5+F5 -> 0 | O5: =M5+N5 -> 0
G6: =E6+F6 -> 0 | I6: Bidofood | K6: 45958 | L6: 40818864 | M6: 296.68 | O6: =M6+N6 -> 296.68
G7: =E7+F7 -> 0 | I7: Bidofood | K7: 45960 | L7: 40860315 | M7: 293.14 | O7: =M7+N7 -> 293.14
A8: Bidfood | C8: 45930 | D8: 40268855 | E8: 218.7 | G8: =E8+F8 -> 218.7 | I8: Reynolds | K8: 45959 | L8: 250573760 | M8: 138.13 | O8: =M8+N8 -> 138.13
A9: Reynolds | C9: 45927 | D9: 850062877 | E9: -4.24 | G9: =E9+F9 -> -4.24 | I9: Reynolds | K9: 45869 | L9: 250395189 | M9: 133.85 | O9: =M9+N9 -> 133.85
A10: Reynolds | C10: 45929 | D10: 250510967 | E10: 147.82 | G10: =E10+F10 -> 147.82 | O10: =M10+N10 -> 0
A11: Bidfood | C11: 45927 | D11: 40230696 | E11: 291.79 | G11: =E11+F11 -> 291.79 | O11: =M11+N11 -> 0
A12: Reynolds | C12: 45917 | D12: 250486796 | E12: 91.51 | G12: =E12+F12 -> 91.51 | O12: =M12+N12 -> 0
A13: Reynolds | C13: 45887 | D13: 250427064 | E13: 132.94 | G13: =E13+F13 -> 132.94 | I13: Petty Cash | K13: 45937.338 | L13: Waitrose & Partners | M13: 3.26 | O13: =M13+N13 -> 3.26
G14: =E14+F14 -> 0 | I14: Petty Cash | K14: 45939.835 | L14: Waitrose & Partners | M14: 6.1 | O14: =M14+N14 -> 6.1
G15: =E15+F15 -> 0 | I15: Petty Cash | K15: 45940.372 | L15: Waitrose & Partners | M15: 2.31 | O15: =M15+N15 -> 2.31
G16: =E16+F16 -> 0 | I16: Petty Cash | K16: 45945.334 | L16: Waitrose & Partners | M16: 9.15 | O16: =M16+N16 -> 9.15
G17: =E17+F17 -> 0 | I17: Petty Cash | K17: 45947.673 | L17: Waitrose & Partners | M17: 4.6 | O17: =M17+N17 -> 4.6
A18: Petty Cash | C18: 45899.945 | D18: Tesco | E18: 8.5 | G18: =E18+F18 -> 8.5 | I18: Petty Cash | K18: 45954.332 | L18: Tesco | M18: 5.05 | O18: =M18+N18 -> 5.05
A19: Petty Cash | C19: 45899.662 | D19: Waitrose & Partners | E19: 8 | G19: =E19+F19 -> 8 | I19: Petty Cash | K19: 45955.338 | L19: Tesco | M19: 6 | O19: =M19+N19 -> 6
A20: Petty Cash | C20: 45901.403 | D20: Waitrose & Partners | E20: 13.2 | G20: =E20+F20 -> 13.2 | I20: Petty Cash | K20: 45956.631 | L20: Waitrose & Partners | M20: 8 | O20: =M20+N20 -> 8
A21: Petty Cash | C21: 45901.792 | D21: Waitrose & Partners | E21: 2.07 | G21: =E21+F21 -> 2.07 | I21: Petty Cash | K21: 45958.536 | L21: Waitrose & Partners | M21: 5.9 | O21: =M21+N21 -> 5.9
A22: Petty Cash | C22: 45903.363 | D22: Waitrose & Partners | E22: 5.03 | G22: =E22+F22 -> 5.03 | O22: =M22+N22 -> 0
A23: Petty Cash | C23: 45905.751 | D23: Waitrose & Partners | E23: 1.7 | G23: =E23+F23 -> 1.7 | O23: =M23+N23 -> 0
A24: Petty Cash | C24: 45909.782 | D24: Waitrose & Partners | E24: 4.6 | G24: =E24+F24 -> 4.6 | O24: =M24+N24 -> 0
A25: Petty Cash | C25: 45910.308 | D25: Tesco | E25: 6.28 | G25: =E25+F25 -> 6.28 | O25: =M25+N25 -> 0
A26: Petty Cash | C26: 45913.294 | D26: Tesco | E26: 9.26 | G26: =E26+F26 -> 9.26 | O26: =M26+N26 -> 0
A27: Petty Cash | C27: 45915.323 | D27: Waitrose & Partners | E27: 8.54 | G27: =E27+F27 -> 8.54 | O27: =M27+N27 -> 0
A28: Petty Cash | C28: 45918.556 | D28: Waitrose & Partners | E28: 7.8 | G28: =E28+F28 -> 7.8 | O28: =M28+N28 -> 0
A29: Petty Cash | C29: 45924.301 | D29: Tesco | E29: 5.25 | G29: =E29+F29 -> 5.25 | O29: =M29+N29 -> 0
G30: =E30+F30 -> 0 | O30: =M30+N30 -> 0
G31: =E31+F31 -> 0 | O31: =M31+N31 -> 0
G32: =E32+F32 -> 0 | O32: =M32+N32 -> 0
A33: Bidofood | C33: 45932 | D33: 40326614 | E33: 185.38 | G33: =E33+F33 -> 185.38 | O33: =M33+N33 -> 0
A34: Bidofood | C34: 45934 | D34: 40369535 | E34: 222.96 | G34: =E34+F34 -> 222.96 | O34: =M34+N34 -> 0
A35: Bidofood | C35: 45937 | D35: 94133662 | E35: -64.85 | G35: =E35+F35 -> -64.85 | O35: =M35+N35 -> 0
A36: Bidofood | C36: 45937 | D36: 40414366 | E36: 177.37 | G36: =E36+F36 -> 177.37 | O36: =M36+N36 -> 0
A37: Bidofood | C37: 45939 | D37: 40462673 | E37: 181.01 | G37: =E37+F37 -> 181.01 | O37: =M37+N37 -> 0
A38: Bidofood | C38: 45941 | D38: 40509493 | E38: 388.38 | G38: =E38+F38 -> 388.38 | O38: =M38+N38 -> 0
A39: Bidofood | C39: 45944 | D39: 94144660 | E39: -9.2 | G39: =E39+F39 -> -9.2 | O39: =M39+N39 -> 0
A40: Bidofood | C40: 45944 | D40: 40549088 | E40: 407.48 | G40: =E40+F40 -> 407.48 | O40: =M40+N40 -> 0
...

Sheet Beverage HOTEL
A1: Beverage Invoices from Hotel | K1: Beverage Provisions (Invoices sent After cut off)
A2: Supplier | B2: SENT | C2: Date | D2: Invoice number | E2: Wine Excl. VAT | F2: Beer & Bottled Bev Excl. VAT | G2: Soft Drinks Excl. VAT | H2: Spirits Excl. VAT | I2: Bev Excl. VAT | K2: Supplier | L2: SENT | M2: Date | N2: Invoice number | O2: Wine Excl. VAT | P2: Beer & Bottled Bev Excl. VAT | Q2: Soft Drinks Excl. VAT | R2: Spirits Excl. VAT | S2: Bev Excl. VAT
A3: Monthly amount | E3: =SUM(E4:E279) -> 0 | F3: =SUM(F4:F279) -> 0 | G3: =SUM(G4:G279) -> 0 | H3: =SUM(H4:H279) -> 0 | I3: =SUM(I4:I279) -> 0 | K3: Monthly amount | O3: =SUM(O4:O279) -> 0 | P3: =SUM(P4:P279) -> 0 | Q3: =SUM(Q4:Q279) -> 0 | R3: =SUM(R4:R279) -> 0 | S3: =SUM(S4:S279) -> 0 | U3: SUPPLIERS
A4: REVERSE PROVISONS (-) M-1 | I4: =E4+F4+G4+H4 -> 0 | S4: =O4+P4+Q4+R4 -> 0 | U4: REVERSE PROVISONS (-) M-1 | V4: YES
I5: =E5+F5+G5+H5 -> 0 | S5: =O5+P5+Q5+R5 -> 0 | U5: MATTHEW CLARK WHOLESALE | V5: NO
I6: =E6+F6+G6+H6 -> 0 | S6: =O6+P6+Q6+R6 -> 0 | U6: PETTY CASH BEV
I7: =E7+F7+G7+H7 -> 0 | S7: =O7+P7+Q7+R7 -> 0
I8: =E8+F8+G8+H8 -> 0 | S8: =O8+P8+Q8+R8 -> 0
I9: =E9+F9+G9+H9 -> 0 | S9: =O9+P9+Q9+R9 -> 0
I10: =E10+F10+G10+H10 -> 0 | S10: =O10+P10+Q10+R10 -> 0
I11: =E11+F11+G11+H11 -> 0 | S11: =O11+P11+Q11+R11 -> 0
I12: =E12+F12+G12+H12 -> 0 | S12: =O12+P12+Q12+R12 -> 0
I13: =E13+F13+G13+H13 -> 0 | S13: =O13+P13+Q13+R13 -> 0
I14: =E14+F14+G14+H14 -> 0 | S14: =O14+P14+Q14+R14 -> 0
I15: =E15+F15+G15+H15 -> 0 | S15: =O15+P15+Q15+R15 -> 0
I16: =E16+F16+G16+H16 -> 0 | S16: =O16+P16+Q16+R16 -> 0
I17: =E17+F17+G17+H17 -> 0 | S17: =O17+P17+Q17+R17 -> 0
I18: =E18+F18+G18+H18 -> 0 | S18: =O18+P18+Q18+R18 -> 0
... I291: =E291+F291+G291+H291 -> 0 | S291: =O291+P291+Q291+R291 -> 0

Sheet Comps
A2: STAFF FOOD
A4: Hotel name: | B4: =_xlfn.SINGLE('Marge Brut'!#REF!) -> #REF!
A5: Current month: | B5: =_xlfn.SINGLE('Marge Brut'!#REF!) -> #REF!
A8: Unit Staff Meal Cost : | B8: 3.2
A10: Department | B10: FT Employee | C10: No of meals per pers. | D10: Total of meals | E10: Cost | F10: Centre
A11: ADMIN | B11: 1 | C11: 12 | D11: =+B11*C11 -> 12 | E11: =+D11*$B$8 -> 38.4 | F11: 6HA1
A12: Reception | B12: 8 | C12: 6.25 | D12: =+B12*C12 -> 50 | E12: =+D12*$B$8 -> 160 | F12: 2AA
A13: Restaurant | B13: 3 | C13: 6.25 | D13: =+B13*C13 -> 18.75 | E13: =+D13*$B$8 -> 60 | F13: 3AZ
A14: Kitchen | D14: =+B14*C14 -> 0 | E14: =+D14*$B$8 -> 0 | F14: 3QZ
A15: Maintenance/ Security | B15: 1 | C15: 15 | D15: =+B15*C15 -> 15 | E15: =+D15*$B$8 -> 48 | F15: 6MZ
A16: Human Resource | D16: =+B16*C16 -> 0 | E16: =+D16*$B$8 -> 0 | F16: 6FA
A17: Housekeeping | D17: =+B17*C17 -> 0 | E17: =+D17*$B$8 -> 0 | F17: 2GZ
A18: TOTAL | B18: =SUM(B11:B17) -> 13 | C18: =AVERAGE(C11:C17) -> 9.875 | D18: =SUM(D11:D17) -> 95.75 | E18: =SUM(E11:E17) -> 306.4
A21: COMPLIMENTARY F&B GIFT TO GUEST & VOUCHERS
A23: Cost of Sales Ratio (%) : | B23: 0.33 | C23: (to be posted to calculate the cost of complementary : should not be superior
C24: to your cumulative cost of sales ratio)
A26: Group | B26: Wine | C26: Draught & Bottled Bev | D26: Soft Drinks Only | E26: Spirit | F26: Total Beverage | G26: Food | H26: Grand total
A27: Breakfast Offer (INC VAT) | H27: =SUM(F27+G27) -> 0
A28: Breakfast Discount (INC VAT) | H28: =SUM(F28+G28) -> 0
A29: Total Breakfast (INC VAT) | G29: =SUM(G27:G28) -> 0 | H29: =SUM(F29+G29) -> 0
A30: Cost Breakfast (EX VAT) | G30: =(G29/1.05)*B23 -> 0 | H30: =SUM(F30+G30) -> 0
A31: Bar Lunch (INC VAT) | F31: =SUM(B31:E31) -> 0 | H31: =SUM(F31+G31) -> 0
A32: Bar Lunch Discount (INC VAT) | F32: =SUM(B32:E32) -> 0 | G32: 0 | H32: =SUM(F32+G32) -> 0
A33: Total Bar Lunch (INC VAT) | B33: =SUM(B31:B32) -> 0 | C33: =SUM(C31:C32) -> 0 | D33: =SUM(D31:D32) -> 0 | E33: =SUM(E31:E32) -> 0 | F33: =SUM(F31:F32) -> 0 | G33: =SUM(G31:G32) -> 0 | H33: =SUM(F33+G33) -> 0
A34: Restaurant Dinner Offer (INC VAT) | F34: =SUM(B34:E34) -> 0 | H34: =SUM(F34+G34) -> 0
A35: Restaurant Dinner Discount (INC VAT) | F35: =SUM(B35:E35) -> 0 | H35: =SUM(F35+G35) -> 0
A36: Total Restaurant Dinner (INC VAT) | B36: =SUM(B34:B35) -> 0 | C36: =SUM(C34:C35) -> 0 | D36: =SUM(D34:D35) -> 0 | E36: =SUM(E34:E35) -> 0 | F36: =SUM(F34:F35) -> 0 | G36: =SUM(G34:G35) -> 0 | H36: =SUM(F36+G36) -> 0
A37: Bar Dinner Offer (INC VAT) | B37: 224.25 | C37: 240.3 | D37: 119 | F37: =SUM(B37:E37) -> 583.55 | G37: 22.8 | H37: =SUM(F37+G37) -> 606.35
A38: Bar Dinner Discount (INC VAT) | F38: =SUM(B38:E38) -> 0 | G38: 8.9 | H38: =SUM(F38+G38) -> 8.9
A39: Total Bar Dinner (INC VAT) | B39: =SUM(B37:B38) -> 224.25 | C39: =SUM(C37:C38) -> 240.3 | D39: =SUM(D37:D38) -> 119 | E39: =SUM(E37:E38) -> 0 | F39: =SUM(F37:F38) -> 583.55 | G39: =SUM(G37:G38) -> 31.7 | H39: =SUM(F39+G39) -> 615.25
A40: Restaurant Lunch Offer (INC VAT) | F40: =SUM(B40:E40) -> 0 | H40: =SUM(F40+G40) -> 0
A41: Restaurant Lunch Discount (INC VAT) | F41: =SUM(B41:E41) -> 0 | H41: =SUM(F41+G41) -> 0
A42: Total Restaurant Lunch (INC VAT) | B42: =SUM(B40:B41) -> 0 | C42: =SUM(C40:C41) -> 0 | D42: =SUM(D40:D41) -> 0 | E42: =SUM(E40:E41) -> 0 | F42: =SUM(F40:F41) -> 0 | G42: =SUM(G40:G41) -> 0 | H42: =SUM(F42+G42) -> 0
A43: Current Month Offer (inc vat) | B43: =(B29+B33+B36+B39+B42) -> 224.25 | C43: =(C29+C33+C36+C39+C42) -> 240.3 | D43: =(D29+D33+D36+D39+D42) -> 119 | E43: =(E29+E33+E36+E39+E42) -> 0 | F43: =(F29+F33+F36+F39+F42) -> 583.55 | G43: =(G29+G33+G36+G39+G42) -> 31.7 | H43: =F43+G43 -> 615.25
A44: CURRENT MONTH COST | B44: =(B43/1.2)*B23 -> 61.66875 | C44: =(C43/1.2)*B23 -> 66.0825 | D44: =(D43/1.2)*$B$23 -> 32.725 | E44: =(E43/1.2)*$B$23 -> 0 | F44: =B44+C44+D44+E44 -> 160.47625 | G44: =(G43/1.2)*$B$23 -> 8.7175 | H44: =F44+G44 -> 169.19375
A46: COMPLIMENTARY MANAGEMENT SUMMARY
A47: Used by Management | D47: 23.8 | F47: =SUM(B47:E47) -> 23.8 | H47: =F47+G47 -> 23.8
A48: Used by Management COS | B48: =(B47/1.2)*B23 -> 0 | C48: =(C47/1.2)*B23 -> 0 | D48: =(D47/1.2)*$B$23 -> 6.545 | E48: =(E47/1.2)*$B$23 -> 0 | F48: =B48+C48+D48+E48 -> 6.545 | G48: =(G47/1.2)*$B$23 -> 0 | H48: =F48+G48 -> 6.545
A51: COMPLIMENTARY ROOMS GIFT TO GUEST & VOUCHERS
A53: Cost of Sales Ratio (%) : | B53: 0.33 | C53: (to be posted to calculate the cost of complementary : should not be superior
...

Sheet Journal
B1: ACCOUNT JOURNAL
A4: Hotel name: | B4: =+_xlfn.SINGLE('Marge Brut'!#REF!) -> #REF!
A5: Current month: | B5: =+_xlfn.SINGLE('Marge Brut'!#REF!) -> #REF!
A7: MARGE BRUTE JOURNAL ( USE STDRC3 - Standard Recurring Journal )
A9: CODE | B9: C/C | C9: Dr | D9: Cr | E9: DESCRIPTION OF JOURNAL
A11: 474000 | C11: ='Marge Brut'!G5 -> 1092.6 | E11: REVERSAL OF PREV MONTHS FOOD PROVISIONS
A12: 600100 | D12: =+C11 -> 1092.6
A13: 474001 | C13: ='Marge Brut'!G12 -> 0 | E13: REVERSAL OF PREV MONTHS BEVG PROVISIONS
A14: 600500 | D14: =+C13 -> 0
A15: 600100 | C15: =+'Marge Brut'!H5 -> 912.17 | E15: PROVISIONS CURRENT MONTH FOOD
A16: 474000 | D16: =+C15 -> 912.17
A17: 600500 | C17: =+'Marge Brut'!H12 -> 0 | E17: PROVISIONS CURRENT MONTH BEVERAGE
A18: 474001 | D18: =+C17 -> 0
A19: 600100 | C19: =+'Marge Brut'!E5 -> 2381.14 | E19: REVERSE FOOD STOCK
A20: 300002 | D20: =+C19 -> 2381.14
A21: 300002 | C21: =+'Marge Brut'!J5 -> 1879.36 | E21: CLOSING FOOD STOCK
A22: 600100 | D22: =+C21 -> 1879.36
A23: 600500 | C23: =+'Marge Brut'!E12 -> 1948.02 | E23: REVERSE BEVERAGE STOCK
A24: 300006 | D24: =+C23 -> 1948.02
A25: 300006 | C25: =+'Marge Brut'!J12 -> 1434.47 | E25: CLOSING BEVERAGE STOCK
A26: 600500 | D26: =+C25 -> 1434.47
A27: 661150 | B27: 6GZ | C27: =+Comps!G48 -> 0 | E27: COMPLIMENTARY FOOD MANAGEMENT
A28: 661161 | B28: 3ZZ | C28: =+Comps!G44 -> 8.7175 | E28: COMPLIMENATRY FOOD GIFT TO GUEST F&B
A29: 661161 | B29: 2CF | C29: =+Comps!G74 -> 0 | E29: COMPLIMENATRY FOOD GIFT TO GUEST ROOMS
A30: 661160 | B30: 6IB7 | C30: =Comps!G100 -> 0 | E30: COMPLIMENATRY FOOD MARKETING
A31: 618400 | B31: 6HA1 | C31: =+Comps!E11 -> 38.4 | E31: STAFF FOOD ADMIN
A32: 618400 | B32: 2AA | C32: =+Comps!E12 -> 160 | E32: STAFF FOOD RECEPTION
A33: 618400 | B33: 3AZ | C33: =+Comps!E13 -> 60 | E33: STAFF FOOD RESTAURANT
A34: 618400 | B34: 3QZ | C34: =+Comps!E14 -> 0 | E34: STAFF FOOD KITCHEN
A35: 618400 | B35: 6MZ | C35: =+Comps!E15 -> 48 | E35: STAFF FOOD MTCE
A36: 618400 | B36: 6BF | C36: =+Comps!E16 -> 0 | E36: STAFF FOOD HUMAN RESOURCE
A37: 618400 | B37: 2GZ | C37: =+Comps!E17 -> 0 | E37: STAFF FOOD HOUSE KEEPING
A38: 600100 | D38: =SUM(C27:C37) -> 315.1175 | E38: COST OF SALES - FOOD
A39: 661150 | B39: 6GZ | C39: =+Comps!F48 -> 6.545 | E39: COMP BEVERAGE MANAGEMENT
A40: 661161 | B40: 3ZZ | C40: =+Comps!F44 -> 160.47625 | E40: COMP BEVERAGE GIFT TO GUEST F&B
A41: 661161 | B41: 2CF | C41: =Comps!F74 -> 4.4825 | E41: COMP BEVERAGE GIFT TO GUEST ROOMS
A42: 661160 | B42: 6IB7 | C42: =Comps!F100 -> 0 | E42: COMP BEVERAGE MARKETING
A43: 600500 | D43: =+C39+C40+C41+C42 -> 171.50375
A44: 664610 | B44: 6GZ | E44: TRANSFER OF F&B COMPLIMENTARY/PSA
A45: 661150 | B45: 6GZ | E45: TRANSFER OF F&B COMPLIMENTARY/PSA
...

Sheet Help Sheet 
B6: Marge Brut | C6: TURNOVER | E6: STOCK | I6: TOTAL | M6: Consumption | N6: Ratio %
B7: Summary | C7: Incl. | D7: Excl. VAT | E7: Opening | F7: Purchases | G7: Reverse | H7: New | I7: All | J7: Closing | K7: Staff | L7: Complimentary. | M7: Month | N7: M.B.
C8: VAT | D8: Month | E8: Stock | G8: Provisions | H8: Provisions | I8: Stocks | J8: Stock | K8: Meal | N8: Month
B9: TOTAL FOOD | C9: 18629.87 | D9: 15524.892 | E9: 2914.98 | F9: 7355.93 | G9: 1885.52 | H9: 2531.68 | I9: 10917.07 | J9: 2847.93 | K9: 1108.8 | L9: 28.5065 | M9: 6931.8335 | N9: 0.44649803
B10: Total Food - (Breakfast) | C10: 2147.47 | D10: 1789.5583 | E10: 786.67 | F10: 558.6 | G10: 196.4 | H10: 266.05 | I10: 1414.92 | J10: 732.28 | L10: 28.5065 | M10: 654.1335 | N10: 0.3655279
B11: Total Breakfast | C11: 16482.4 | D11: 13735.333 | E11: 2128.31 | F11: 6797.33 | G11: 1689.12 | H11: 2265.63 | I11: 9502.15 | J11: 2115.65 | L11: 0 | M11: 7386.5 | N11: 0.53777363
B12: WINES | C12: 1714.8725 | D12: 1429.0604 | E12: 796.9 | F12: 558.18 | G12: 437.45 | H12: 0 | I12: 917.63 | J12: 343.13 | L12: 94.59175 | M12: 479.90825 | N12: 0.33582083
B13: BEER | C13: 3006.5125 | D13: 2505.4271 | E13: 877.92 | F13: 1211.63 | G13: 738.38 | H13: 0 | I13: 1351.17 | J13: 394.19 | L13: 69.542 | M13: 887.438 | N13: 0.35420628
B14: BOTTLED / SOFT | C14: 2398.7125 | D14: 1998.9271 | E14: 1181.26 | F14: 592.35 | G14: 623 | H14: 0 | I14: 1150.61 | J14: 721.47 | L14: 31.88075 | M14: 397.25925 | N14: 0.19873624
B15: SPIRIT | C15: 2720.8825 | D15: 2267.4021 | E15: 855.57 | F15: 519.47 | G15: 409.05 | H15: 0 | I15: 965.99 | J15: 368.54 | L15: 28.1765 | M15: 569.2735 | N15: 0.25106861
B16: TOTAL BEVERAGE | C16: 9840.98 | D16: 8200.8167 | E16: 3711.65 | F16: 2881.63 | G16: 2207.88 | H16: 0 | I16: 4385.4 | J16: 1827.33 | L16: 224.191 | M16: 2333.879 | N16: 0.28459105
B17: GRAND TOTAL VR | C17: 28470.85 | D17: 23725.708 | E17: 6626.63 | F17: 10237.56 | G17: 4093.4 | H17: 2531.68 | I17: 15302.47 | J17: 4675.26 | K17: 1108.8 | L17: 252.6975 | M17: 9265.7125 | N17: 0.3905347
B18: GRAND TOTAL FOLS | C18: =16482.4+2147.47+9840.98 -> 28470.85 | F18: =+C17-C18 -> 0 | G18: Must be 0
B19: Purchases Control | C19: Beverage | F19: =+F16-F15-F14-F13-F12 -> 0 | G19: Must be 0 | J19: by accountant
B20: Purchases Control | C20: Food | F20: =F9-F10-F11 -> 0 | G20: Must be 0 | J20: by hotel
J21: Accountant
B26: TURNOVER
B27: The amount of money taken by a business in a particular period.
B28: Extract the report from Bizzon - Montly Regulation should have been done day before to match FOLS revenue | L28: Open the Excel Report received on the email > Click on "Report" tab > Scroll down to Categories section of the report | X28: Enter the revenue per category on MB
B47: OPENING STOCK
B48: Figures to be copied from previous month's closing stock.
B51: PURCHASES
B52: Total of all invoices send to accounting centre from hotel and entered into Grandback to 600100/ 600500 for the financial month
B54: FOOD REVERSE PROVISION
B55: Figures to be copied from previous month's F&B provisions
B57: FOOD PROVISION
B58: In a company's accounts, an amount of money that is kept in case of a possible future loss or debt.
B59: In Marge Brut, this section contains FOOD INVOICE AMOUNT between END OF FINANCIAL MONTH and END OF CALENDAR MONTH.
B61: CLOSING STOCK
B62: The goods that a business has available for sale at the end of an accounting period, or the value of those goods.
B63: This MONTH closing stock it will be in the next MONTH (M+1) opening stock.
... B80: Report number of emplyees and number of staff meals taken per employee during the month
B82: Unit Staff Meal Cost : | C82: 3.2
B84: Department | C84: FT Employee | D84: No of meals per pers. | E84: Total of meals | F84: Cost | G84: Centre
B85: ADMIN | C85: 2 | D85: 21 | E85: =+C85*D85 -> 42 | F85: =+E85*$B$8 -> 0 | G85: 6HA1
B86: Reception | C86: 10.5 | D86: 21 | E86: =+C86*D86 -> 220.5 | F86: =+E86*$B$8 -> 0 | G86: 2AA
B87: Restaurant | C87: 2.5 | D87: 21 | E87: =+C87*D87 -> 52.5 | F87: =+E87*$B$8 -> 0 | G87: 3AZ
B88: Kitchen | E88: =+C88*D88 -> 0 | F88: =+E88*$B$8 -> 0 | G88: 3QZ
B89: Maintenance/ Security | C89: 1.5 | D89: 21 | E89: =+C89*D89 -> 31.5 | F89: =+E89*$B$8 -> 0 | G89: 6MZ
B90: Human Resource | E90: =+C90*D90 -> 0 | F90: =+E90*$B$8 -> 0 | G90: 6FA
...

Sheet F&B WRONG ALLOCATION

Sheet FB Posting Bizzon
A1: Food and Beverage Posing - Bizzon
A2: Any Food or Beverage items served, used or wasted must be posted on Bizzon
A5: Complimentary The food or beverage item has been served / used. | B5: Drink Voucher - Gift to Guest | C5: • Drink Vouchers redeemed by ALL members
C6: • Any "gifts" given to guets - Including Sparkles
B9: Marketing | C9: • Food and bevergae use for marketing i.e. show around for a potential client, drinks given to a social media influencer staying with us, etc
B13: Management Account | C13: • Items used by the hotel management team. i.e. interviews, meetings, etc
B17: Customer Complaint | C17: • Any items given to customers relating to complaints, including breakfasts
A22: Discount The food or beverage item has been served / used. | B22: Heartist Discount - 30% | C22: • Discount given to Heartists (Accor employees)
B24: Friends & Family - 30% | C24: • Discount given to Family and Frinds from Accor employees (must be staying in the hotel)
B25: Other Discount - % Variable | C25: • Any other discount offered - Reason must be stated on Bizzon
A29: Void The food or beverage item has NOT been served / used with the exception of wastage | B29: Wastage | C29: • Items wasted for any reason i.e. broken, expired, lost (customer left without paying), etc
B30: Testing /User/Server Error | C30: • Mistakes during posting where the item did not leave the stock
B32: Customer changed Mind | C32: • If the customer change their mind before the item was served.
B34: Out of stock | C34: • After posting on Bizzon you realise the item is out of stock
